Workbook
Name CLASIFICACION: [1]PANEL!$D$11
Name SUELDOS: '[1]VALOR M.O.'!$B$6:$E$52

Sheet Resumen Oferta
B2: ANEXO N°
B3: Licitación Construcción OOCC Túnel LAT Vitacura - Providencia
B4: RESUMEN DE PRECIOS
C7: Ítem | D7: Total UF
C9: Resumen de Precios
B10: A | C10: Total Costo Directo | D10: =+'A) Detalle Costo Directo'!F360
B11: B | C11: Total Costo Indirecto | D11: =+'B) Detalle C. Ind., GG y Utilid'!G56
B12: C | C12: Total Gastos Generales | D12: =+'B) Detalle C. Ind., GG y Utilid'!G57
B13: D | C13: Utilidades | D13: =+'B) Detalle C. Ind., GG y Utilid'!G58
C15: Total Neto | D15: =+SUM(D10:D13)
C17: IVA | D17: =+D15*0.19
C19: Total | D19: =+D15+D17
D27: Firma y Timbre
D28: Representante Legal del Proponente
A32: Verde: cantidad calculada por modelo | B32: Salmón: precio referencial ONDAC 2026 (UF) | C32: Amarillo: completar con precio oferta

Sheet A) Detalle Costo Directo
A2: ANEXO N°
A3: =+'Resumen Oferta'!B3
A4: DESGLOSE DE COSTO DIRECTO
A6: N° | B6: Ítem | C6: Unidad | D6: Cantidad | E6: Precio Unitario UF | F6: =D6*E6 | G6: Observación | H6: Pago
A7: 1.0 | B7: Actividades Previas de Ingeniería, Procedimientos de Trabajo y Coordinación con Servicios de agua, electricidad, gas, telecomunicaciones | F7: =+SUM(F8:F12) | G7: x
A8: 1.1 | B8: Elaboración y Aprobación de todos los procedimientos de trabajo que sean necesarios para iniciar las obras: Correctas Prácticas con la Comunidad, Programa de Prevención de Riesgos, Habilitación de Instalación de Faenas, Construcción de Cierres Perimetrales, Ejecución de Señalización Vial, Plan de Emergencias, Matriz de Riesgos, Izaje Carga y Descarga y de Construcción Túnel Liner | C8: gl | D8: 1 | F8: =D8*E8 | G8: Etapa 1, Suma alzada
A9: 1.2 | B9: Revisión del Estudio de Levantamiento de Servicios aportado por STM. Comunicación inicial y coordinación con las empresas de servicios de agua, electricidad, telecomunicaciones, gas, la UOCT y municipalidades | C9: gl | D9: 1 | F9: =D9*E9 | G9: Etapa 1, Suma alzada
A10: 1.3 | B10: Memoria de Cálculo Sistema de Izaje y Fundación, Ventilación de Túnels (para construcción) | C10: gl | D10: 1 | F10: =D10*E10 | G10: Etapa 1, Suma alzada
A11: 1.4 | B11: Entrega de Planos As Built | C11: gl | D11: 1 | F11: =D11*E11 | G11: Etapa 2, Suma alzada
A13: 2.0 | B13: Suministros | F13: =+SUM(F14:F22)
A14: 2.1 | B14: Liners de Piques puesto en bodega del proveedor y aprobado por el Cliente (Piques de 4,0 metros de diámetro, espesor de liners de 5mm y galvanizado de 112 micras de espesor promedio) | C14: m | F14: =+D14*E14 | G14: Aporte STM | H14: 5% con el cumplimiento de Condiciones contractuales, 85% por avance proporcional y 10% con la recepción provisional de la obra.
A15: 2.2 | B15: Liners de Túnel puesto en bodega del proveedor y aprobado por el Cliente (2,21 metros de diámetro, espesor de liners de 5mm y galvanizado de 112 micras de espesor promedio) | C15: m | F15: =+D15*E15 | G15: Aporte STM
A16: 2.5 | B16: Jet Fan 3,5kW | C16: und | F16: =+D16*E16 | G16: Aporte STM
A17: 2.6 | B17: Estructuras Galvanizadas de soporte de cables | C17: kg | F17: =+D17*E17 | G17: Aporte STM
A18: 2.7 | B18: Estructuras de Cobertura de Piques | C18: kg | F18: =+D18*E18 | G18: Aporte STM
A19: 2.8 | B19: Estructuras Galvanizadas de Escalas, barandas y Plataformas | C19: kg | F19: =+D19*E19 | G19: Aporte STM
A20: 2.9 | B20: Otras Estructuras | C20: kg | F20: =+D20*E20 | G20: Aporte STM
A21: 2.10 | B21: Sistema de Planta Elevadora de Agua | C21: gl | F21: =+D21*E21 | G21: Aporte STM
A23: 3.0 | B23: Instalación de Faenas | F23: =+SUM(F24:F39)
A24: 3.1 | B24: Cierres Perimetrales Piques 02 a 08. Suministro, Retiro y Disposición final | C24: gl | D24: 1 | F24: =D24*E24 | G24: Etapa 2, Suma alzada | H24: 5% con el cumplimiento de Condiciones contractuales, 85% por avance proporcional y 10% con la recepción provisional de la obra
A25: 3.2 | B25: Portones Cierres Perimetrales Piques 02 a 08. Suministro, Retiro y Disposición final | C25: gl | D25: 1 | F25: =D25*E25 | G25: Etapa 2, Suma alzada
A26: 3.3 | B26: Bodegas Resnopel Piques 02 a 08 | C26: gl | D26: 1 | F26: =D26*E26 | G26: Etapa 2, Suma alzada
A27: 3.4 | B27: Bodegas Respel Piques 02 al 08 | C27: gl | D27: 1 | F27: =D27*E27 | G27: Etapa 2, Suma alzada
A28: 3.5 | B28: Contenedores Oficina, Bodega y Sala de Cambio Instalaciones de Faena Piques 01 a 08 | C28: gl | D28: 1 | F28: =D28*E28 | G28: Etapa 2, Suma alzada
A29: 3.6 | B29: Baños químicos Instalaciones de Faena Piques 01 a 08 | C29: gl | D29: 1 | F29: =D29*E29 | G29: Etapa 2, Suma alzada
A30: 3.7 | B30: Grupo generador Insonorizado e Instalación Eléctrica Piques 01 a 08 | C30: gl | D30: 1 | F30: =D30*E30 | G30: Etapa 2, Suma alzada
A31: 3.8 | B31: Estanque de recuperación de Agua de Lavado de Canoas, Piques 01 a 09 | C31: gl | D31: 1 | F31: =D31*E31 | G31: Etapa 2, Suma alzada
A32: 3.9 | B32: Instalación para Lavado de Ruedas Piques 02 a 08 | C32: gl | D32: 1 | F32: =D32*E32 | G32: Etapa 2, Suma alzada
A33: 3.10 | B33: Señaléticas, Extintores, Estaciones de Emergencia Piques 01 a 09 | C33: gl | D33: 1 | F33: =D33*E33 | G33: Etapa 2, Suma alzada
A34: 3.11 | B34: Fundación, estructura y equipos de Izaje (piques 01 a 09) | C34: gl | D34: 1 | F34: =D34*E34 | G34: Etapa 2, Suma alzada
A35: 3.12 | B35: Sistemas de Ventilación (piques 01 a 09) | C35: gl | D35: 1 | F35: =D35*E35 | G35: Etapa 2, Suma alzada
A36: 3.13 | B36: Implementación de Sistema de Rescate tipo Brazo pescante en Piques 01 a 09 | C36: gl | D36: 1 | F36: =D36*E36 | G36: Etapa 2, Suma alzada
... A38: 3.15 | B38: Otros elementos necesarios | C38: gl | D38: 1 | F38: =D38*E38 | G38: Etapa 2, Suma alzada
A40: 4.0 | B40: Obras Civiles Piques | F40: =+F41+F58+F74+F90+F106+F122+F138+F154+F170
A41: 4.1 | B41: Pique 1 Túnel Liner | F41: =+SUM(F42:F57)
A42: 4.1.1 | B42: Excavación | C42: m3 | D42: 252.46 | E42: 2.2078 | F42: =D42*E42 | G42: Etapa 2, Suma alzada | H42: 5% con el cumplimiento de Condiciones contractuales, 85% por avance proporcional y 10% con la recepción provisional de la obra.
A43: 4.1.2 | B43: Retiro excavación y transporte a botadero (geométrico) | C43: m3 | D43: 252.46 | E43: 0.9091 | F43: =D43*E43 | G43: Etapa 2, Suma alzada
A44: 4.1.3 | B44: Montaje Liner (Incluyendo sello entre placas y mortero) | C44: m | D44: 20.1 | E44: 5.7143 | F44: =D44*E44 | G44: Etapa 2, Suma alzada
A45: 4.1.4 | B45: Refuerzo Losa Anillo Fondo de Pique | C45: gl | D45: 1 | E45: 72.7273 | F45: =D45*E45 | G45: Etapa 2, Suma alzada
A46: 4.1.5 | B46: Construcción de Dren | C46: gl | D46: 1 | E46: 46.7532 | F46: =D46*E46 | G46: Etapa 2, Suma alzada
...

Sheet B) Detalle C. Ind., GG y Utilid
A2: ANEXO N°
A3: =+'Resumen Oferta'!B3
A4: DESGLOSE DE COSTO INDIRECTO, GASTOS GENERALES Y UTILIDADES
A7: N° | B7: Ítem | C7: Unidad | D7: Cantidad | E7: Tiempo | F7: Precio Unitario | G7: Total UF | H7: Pago
A8: 1.0 | B8: Costos Indirectos de Obra | G8: =+G9+G12+G23+G29+G33
A9: 1.1 | B9: Servicio de Vigilancia de Obra | G9: =+SUM(G10:G11)
A10: 1.1.1 | B10: Servicio de vigilancia 24 horas, incluye guardias, insumos y garita de guardias habilitada | C10: mes | D10: 1 | E10: 24 | F10: 100 | G10: =+D10*E10*F10 | H10: 5% con el cumplimiento de Condiciones contractuales, 85% por avance proporcional y 10% con la recepción provisional de la obra | I10: REF: Servicio vigilancia 24h externalizado
A12: 1.2 | B12: Personal Indirecto | G12: =+SUM(G13:G22)
A13: 1.2.1 | B13: Administrador | C13: mes | D13: 1 | E13: 24 | F13: 150 | G13: =+D13*E13*F13 | H13: 5% con el cumplimiento de Condiciones contractuales, 85% por avance proporcional y 10% con la recepción provisional de la obra | I13: REF: 1 Administrador (~$5.8M CLP/mes)
A14: 1.2.2 | B14: Jefe de Terreno | C14: mes | D14: 1 | E14: 24 | F14: 120 | G14: =+D14*E14*F14 | I14: REF: 1 Jefe de Terreno (~$4.6M CLP/mes)
A15: 1.2.3 | B15: Supervisor | C15: mes | D15: 2 | E15: 24 | F15: 90 | G15: =+D15*E15*F15 | I15: REF: 2 Supervisores en turnos
A16: 1.2.4 | B16: Encargado de Prevención de Riesgos | C16: mes | D16: 1 | E16: 24 | F16: 80 | G16: =+D16*E16*F16 | I16: REF: 1 Encargado Prevencion Riesgos
A17: 1.2.5 | B17: Encargado de Medio Ambiente | C17: mes | D17: 1 | E17: 24 | F17: 70 | G17: =+D17*E17*F17 | I17: REF: 1 Encargado Medio Ambiente
A18: 1.2.6 | B18: Topógrafo | C18: mes | D18: 1 | E18: 24 | F18: 80 | G18: =+D18*E18*F18 | I18: REF: 1 Topografo
A19: 1.2.7 | B19: Trazador | C19: mes | D19: 1 | E19: 24 | F19: 55 | G19: =+D19*E19*F19 | I19: REF: 1 Trazador
A20: 1.2.8 | B20: Bodeguero | C20: mes | D20: 1 | E20: 24 | F20: 50 | G20: =+D20*E20*F20 | I20: REF: 1 Bodeguero
A21: 1.2.9 | B21: Otros (Desglosar)
A23: 1.3 | B23: Maquinarias, Equipos y Vehículos (Desglosar) | G23: =+SUM(G24:G28)
A24: 1.3.1 | B24: Camioneta | C24: und | D24: 3 | E24: 24 | F24: 35 | G24: =+D24*E24*F24 | H24: 5% con el cumplimiento de Condiciones contractuales, 85% por avance proporcional y 10% con la recepción provisional de la obra | I24: REF: 3 Camionetas operativas
A25: 1.3.2 | B25: Fletes | C25: und | D25: 1 | E25: 24 | F25: 50 | G25: =+D25*E25*F25 | I25: REF: Fletes mensuales
A26: 1.3.3 | B26: Andamios | C26: gl | D26: 1 | E26: 24 | F26: 30 | G26: =+D26*E26*F26 | I26: REF: Arriendo andamios
A27: 1.3.4 | B27: Maquinarias y equipos menores | C27: gl | D27: 1 | E27: 24 | F27: 80 | G27: =+D27*E27*F27 | I27: REF: Equipos menores (grupos, compresor)
A29: 1.4 | B29: Gastos de Disposición de Resíduos | G29: =+SUM(G30:G32)
A30: 1.4.1 | B30: Disposición de Resíduos | C30: gl | D30: 1 | E30: 24 | F30: 50 | G30: =+D30*E30*F30 | H30: 5% con el cumplimiento de Condiciones contractuales, 85% por avance proporcional y 10% con la recepción provisional de la obra | I30: REF: Disposicion residuos sólidos
A31: 1.4.2 | B31: Disposición de Excedentes de la Obra | C31: gl | D31: 1 | E31: 24 | F31: 120 | G31: =+D31*E31*F31 | I31: REF: Disposicion excedentes excavación
A33: 1.6 | B33: Otros (Desglosar) | G33: =+SUM(G34:G45)
A34: 1.6.1 | G34: =+D34*E34*F34 | H34: 5% con el cumplimiento de Condiciones contractuales, 85% por avance proporcional y 10% con la recepción provisional de la obra
A35: 1.6.2 | G35: =+D35*E35*F35
A36: 1.6.3 | G36: =+D36*E36*F36
A38: 1.7 | B38: Cobros por Cambios Previsto. Costo por semana de retraso del Mandante en la entrega de los Permisos del Mandante | G38: =+SUM(G39:G45)
A39: 1.7.1 | B39: Costo único a cobrar por mes de retraso del Mandante en su plazo de entrega de los Permisos del Mandante, por sobre los 210 días establecidos en las Bases Técnicas | C39: semana | D39: 4 | G39: =+D39*E39*F39 | H39: Partida a precio unitario 90% por avance proporcional y 10% con la recepción provisional de la obra
A41: 1.8 | B41: Cobros por Cambios Previsto. Paralizaciones por responsabilidad del Mandante [definiciones en Bases Técnicas] | G41: =+SUM(G42:G47)
A42: 1.8.1 | B42: Costo de Desmovilización de Personal de un frente de trabajo. | C42: gl | D42: 3 | G42: =+D42*E42*F42 | H42: Partida a precio unitario 90% por avance proporcional y 10% con la recepción provisional de la obra
A43: 1.8.2 | B43: Costo de Mantrener la Instalación de Faenas y la Vigilancia durante la paralización | C43: semana | D43: 10 | G43: =+D43*E43*F43 | H43: Partida a precio unitario 90% por avance proporcional y 10% con la recepción provisional de la obra
A44: 1.8.3 | B44: Costo de Extensión de Plazos de toda la Obra por Razones del Mandante, descontados los retrasos del Contratista | C44: semana | D44: 10 | G44: =+D44*E44*F44 | H44: Partida a precio unitario 90% por avance proporcional y 10% con la recepción provisional de la obra
A46: 2.0 | B46: Gastos Generales | G46: =+SUM(G47:G51)
A47: 2.1 | B47: Aporte a Oficina Central | C47: gl | D47: 1 | E47: 1 | F47: 3200 | G47: =+D47*E47*F47 | H47: 5% con el cumplimiento de Condiciones contractuales, 85% por avance proporcional y 10% con la recepción provisional de la obra | I47: REF: Aporte oficina central ~4.4% directo
A48: 2.2 | B48: Gastos Financieros | C48: gl | D48: 1 | E48: 1 | F48: 1800 | G48: =+D48*E48*F48 | I48: REF: Gastos financieros ~2.5% directo
A49: 2.3 | B49: Boletas de Garantía y Seguros | C49: gl | D49: 1 | E49: 1 | F49: 1200 | G49: =+D49*E49*F49 | I49: REF: Boletas garantia + seguros ~1.6% directo
A50: 2.4 | B50: Otros (Desglosar)
...

Sheet Análisis de Precios
A1: ANÁLISIS DE PRECIOS — TÚNEL LAT VITACURA-PROVIDENCIA
A2: UF referencial: 38,500 CLP (mayo 2026) | Generado: 2026-05-19
A3: ⚠ SUPUESTO: cantidades sección 5 calculadas para 1 túnel Ø2.21m por tramo. Si la licitación requiere 2 túneles paralelos, multiplicar cantidades 5.x por 2.
A5: 1. CUBICACIÓN REALIZADA (cantidades pre-llenadas en hoja A)
A6: Partida | B6: Cant. | C6: Unidad | D6: Ítems licitación | E6: UF est. medio | F6: Fuente / Cómo se calculó
A7: Excavación pique | B7: 1770.35 | C7: m3 | D7: 4.1.1 | E7: 4,868 UF | F7: área(12.57m²) × profundidad(20m)
A8: Retiro excavación | B8: 1770.35 | C8: m3 | D8: 4.1.2 | E8: 2,036 UF | F8: igual excavación — flete botadero
A9: Montaje liner pique | B9: 140.88 | C9: m | D9: 4.1.3 | E9: 845 UF | F9: profundidad pique (20m = 20 anillos)
A10: Montaje escalas+plataformas | B10: 9 | C10: gl | D10: 4.1.8 | E10: 810 UF | F10: 1 gl por pique (STM aporta estructuras)
A11: Brocal definitivo | B11: 9 | C11: gl | D11: 4.1.15 | E11: 1,035 UF | F11: 1 gl por pique
A12: Excavación túnel | B12: 9414.22 | C12: m3 | D12: 5.1-5.8 | E12: 47,071 UF | F12: área(3.84m²) × longitud / 8 tramos
A13: Montaje liner túnel Ø2.21m | B13: 2454.2 | C13: m | D13: 5.1-5.8 | E13: 11,657 UF | F13: longitud tunel / 8 tramos
A14: Radier túnel H30 | B14: 813.57 | C14: m3 | D14: 5.1-5.8 | E14: 6,915 UF | F14: área × espesor(0.15m)
A16: 2. NO CUBICADO — Requiere estudio específico o suma alzada del contratista
A17: Ítem licitación | B17: Unidad | C17: Razón / Recomendación
A18: 4.x.10 Shotcrete | B18: m³ | C18: Depende de clasificación RMR del terreno (geotecnia)
A19: 4.x.11 Malla | B19: kg | C19: Diseño geotécnico — varía según tipo de suelo
A20: 4.x.12 Pernos de convergencia | B20: und | C20: Análisis convergencia-confinamiento requerido
A21: 4.x.4 Refuerzo Losa Anillo Fondo | B21: gl | C21: Suma alzada — cotización directa contratista
A22: 4.x.5 Construcción Dren | B22: gl | C22: Suma alzada — cotización directa contratista
A23: 4.x.6 Terminaciones | B23: gl | C23: Suma alzada — cotización directa contratista
A24: 4.x.7 Cobertura pique | B24: gl | C24: Suma alzada — cotización directa contratista
A25: 4.x.9 Refuerzo apertura | B25: gl | C25: Suma alzada — cotización directa contratista
A26: 4.x.14 Brocal temporal | B26: gl | C26: Suma alzada — cotización directa contratista
A27: Sec. 2 Liner pique Ø4m + liner túnel Ø2.21m | B27: — | C27: Aporte STM: mandante suministra el material liner, contratista instala (ítems 4.x.3, 5.x.3)
A28: Sec. 2 Escalas y plataformas (estructura) | B28: — | C28: Aporte STM: mandante suministra estructura, contratista monta (ítem 4.x.8)
... A32: Sec. 3 Instalación de Faenas | B32: gl | C32: Suma alzada. IF SS Vitacura (STM-IF-20251009): 3 etapas (Túnel Liner / TL+OOEE / OOCC+OOEE). Contenido típico: contenedores oficinas/baños/bodega, compresor, winche, minicargador, acopio liner.
A34: 3. PRECIOS DE REFERENCIA MERCADO CHILE 2026 (estimados — solicitar cotización formal)
A35: Partida | B35: Unidad | C35: UF mín/un | D35: UF máx/un | E35: CLP mín/un (aprox) | F35: Referencia
A36: Excavación pique Ø4m | B36: m³ | C36: 2.00 | D36: 3.50 | E36: $77,000 – $134,750 | F36: ONDAC 2026
A37: Retiro excavación pique | B37: m³ | C37: 0.80 | D37: 1.50 | E37: $30,800 – $57,750 | F37: Mercado Santiago
A38: Montaje liner pique Ø4m (solo inst.) | B38: m | C38: 4.00 | D38: 8.00 | E38: $154,000 – $308,000 | F38: Est. mercado
A39: Shotcrete en pique | B39: m³ | C39: 4.50 | D39: 7.00 | E39: $173,250 – $269,500 | F39: ONDAC 2026
A40: Malla electrosoldada | B40: kg | C40: 0.03 | D40: 0.05 | E40: $1,155 – $1,925 | F40: ONDAC 2026
A41: Montaje escalas+plataformas | B41: gl | C41: 60.00 | D41: 120.00 | E41: $2,310,000 – $4,620,000 | F41: Est. mercado/pique
A42: Brocal definitivo | B42: gl | C42: 80.00 | D42: 150.00 | E42: $3,080,000 – $5,775,000 | F42: Est. mercado
A43: Excavación túnel Ø2.21m | B43: m³ | C43: 3.50 | D43: 6.00 | E43: $134,750 – $231,000 | F43: ONDAC 2026 tunel urbano
A44: Montaje liner túnel Ø2.21m | B44: m | C44: 3.50 | D44: 6.00 | E44: $134,750 – $231,000 | F44: Est. instalación
A45: Radier túnel H30 | B45: m³ | C45: 7.00 | D45: 10.00 | E45: $269,500 – $385,000 | F45: ONDAC 2026
A46: Extractor Soler-Palau TGT/6-1409 (37kW) — 2 un | B46: un | C46: 800.00 | D46: 1200.00 | E46: $30,800,000 – $46,200,000 | F46: STM38110 §3.14 — suministro STM, instalación contratista
...

Sheet Memoria de Cálculo
A1: MEMORIA DE CÁLCULO — TÚNEL LAT 2×110 kV VITACURA-PROVIDENCIA
A2: Documento generado: 2026-05-19 | Licitación: 2025-25-TX-SS-RM | Mandante: STM
A4: 1. CONSTANTES GEOMÉTRICAS
A5: # | B5: Constante | C5: Fórmula | D5: Valor | E5: Unidad | F5: Fuente
A6: 1.1 | B6: Área sección pique | C6: π × r² = π × (4.0/2)² | D6: 12.5664 | E6: m² | F6: STM38136 Ø interior pique
A7: 1.2 | B7: Área sección túnel liner | C7: π × r² = π × (2.21/2)² | D7: 3.8359 | E7: m² | F7: STM38136 Ø interior liner
A8: 1.3 | B8: Radier H30 volumen por metro | C8: ancho × espesor = 2.21 × 0.15 | D8: 0.3315 | E8: m³/m | F8: Diseño estructural radier túnel
A9: 1.4 | B9: Diámetro fundación pique | C9: 4.20 m externo | D9: 4.20 | E9: m | F9: STM38020 detalle típico
A10: 1.5 | B10: Espesor liner acero A-36 | C10: 5 mm | D10: 0.005 | E10: m | F10: STM38019 §5.1 modelo TL
A11: 1.6 | B11: Espesor revestimiento estándar | C11: Liner 5mm + Shotcrete G-30 95mm | D11: 0.10 | E11: m | F11: STM38019 §5.1 (pp.17)
A12: 1.7 | B12: Espesor zona reforzada (apertura ojo demolición) | C12: Liner + Shotcrete + 2do revestimiento | D12: 0.20 | E12: m | F12: STM38019 §5.1
A13: 1.8 | B13: Avance por anillo (pique y túnel) | C13: Excavación + instalación liner secuencial | D13: 0.46 | E13: m | F13: STM38019 §5.1 Tabla 5
A15: 2. PROFUNDIDADES DE PIQUES — NV terreno - NV invert liner
A16: Pique | B16: NV terreno (m.s.n.m) | C16: NV liner invert (m.s.n.m) | D16: Profundidad (m) | E16: Excavación (m³) | F16: Fuente plano
A17: P1 | B17: 625.06 | C17: 604.97 | D17: 20.09 | E17: 252.46 | F17: STM38020
A18: P2 | B18: 621.50 | C18: 602.83 | D18: 18.67 | E18: 234.61 | F18: STM38020
A19: P3 | B19: 619.18 | C19: 601.88 | D19: 17.30 | E19: 217.4 | F19: STM38020
A20: P4 | B20: 612.91 | C20: 597.93 | D20: 14.98 | E20: 188.24 | F20: STM38021
A21: P5 | B21: 610.70 | C21: 595.46 | D21: 15.24 | E21: 191.51 | F21: STM38021
A22: P6 | B22: 607.39 | C22: 591.88 | D22: 15.51 | E22: 194.9 | F22: STM38022
A23: P7 | B23: 603.15 | C23: 587.53 | D23: 15.62 | E23: 196.29 | F23: STM38022
A24: P8 | B24: 599.00 | C24: 584.59 | D24: 14.41 | E24: 181.08 | F24: STM38023
A25: P9 | B25: 591.18 | C25: 582.12 | D25: 9.06 | E25: 113.85 | F25: STM38023
A26: ⚠ Discrepancia P9: STM38109 §2.4 reporta 9.67m (referencia portal vs NV terreno). Diferencia 0.61m × 12.57m² = ~7.7 m³ excavación adicional si se usa cota portal.
A28: 3. LONGITUDES DE TRAMOS — DM piques sucesivos
A29: Tramo | B29: Entre piques | C29: DM inicio (m) | D29: DM fin (m) | E29: Longitud (m) | F29: Fuente plano
A30: T1 | B30: P1-P2 | C30: 0.0 | D30: 389.0 | E30: 389.0 | F30: STM38020
A31: T2 | B31: P2-P3 | C31: 389.0 | D31: 560.6 | E31: 171.6 | F31: STM38020
A32: T3 | B32: P3-P4 | C32: 560.6 | D32: 955.7 | E32: 395.1 | F32: STM38020
A33: T4 | B33: P4-P5 | C33: 955.7 | D33: 1161.6 | E33: 205.9 | F33: STM38021
A34: T5 | B34: P5-P6 | C34: 1161.6 | D34: 1459.4 | E34: 297.8 | F34: STM38021
A35: T6 | B35: P6-P7 | C35: 1459.4 | D35: 1777.4 | E35: 318.0 | F35: STM38022
A36: T7 | B36: P7-P8 | C36: 1777.4 | D36: 2145.1 | E36: 367.7 | F36: STM38022
A37: T8 | B37: P8-P9 | C37: 2145.1 | D37: 2454.2 | E37: 309.1 | F37: STM38023
A39: 4. FÓRMULAS POR PARTIDA
A40: # | B40: Partida | C40: Fórmula aplicada | D40: Cantidad total | E40: Unidad | F40: Validación
A41: 4.1 | B41: Excavación piques | C41: Σ (12.5664 m² × prof_i) para i=1..9 | D41: 1770.34 | E41: m³ | F41: ✓ Coincide con suma manual
A42: 4.2 | B42: Retiro excavación piques | C42: =Excavación pique (igual volumen al botadero) | D42: 1770.34 | E42: m³ | F42: ✓ = Excavación
A43: 4.3 | B43: Montaje liner pique | C43: Σ profundidad_i para i=1..9 | D43: 140.9 | E43: m | F43: =longitud anillo × cantidad anillos
A44: 4.4 | B44: Refuerzo losa anillo fondo (.4) | C44: 1 gl × 9 piques (suma alzada por pique) | D44: 9 | E44: gl | F44: Cant 1 gl/pique — precio cotizar
...
